<?xml version="1.0"?>
<robot xmlns:xacro="http://www.ros.org/wiki/xacro">

  <xacro:include filename="$(find cob_description)/urdf/cob4_sensorring/sensorring.gazebo.xacro" />
  <xacro:include filename="$(find cob_description)/urdf/cob4_sensorring/sensorring.transmission.xacro" />
  
  
  <xacro:macro name="sensorring" params="parent name *origin">

    <joint name="${name}_joint" type="revolute">
      <insert_block name="origin" />
      <parent link="${parent}"/>
      <child link="${name}_link" />
      <calibration rising="${sensorring_ref}"/>
      <axis xyz="0 0 1" />
      <dynamics damping="5.0" friction="0.5"/>
      <limit effort="100" lower="-6.2831" upper="6.2831" velocity="1.4"/>
    </joint>
    
    <link name="${name}_link">
      <inertial>
        <origin xyz="0 0 0" rpy="0 0 0"/>
        <mass value="0.1"/>
        <inertia ixx="0.01" ixy="0" ixz="0" iyy="0.01" iyz="0" izz="0.01" />
      </inertial>
    </link>
    
    <!-- extensions -->
    <xacro:sensorring_gazebo name="${name}" />
    <xacro:sensorring_transmission name="${name}" />

  </xacro:macro>

</robot>
