<?xml version="1.0"?>
<robot xmlns:sensor="http://playerstage.sourceforge.net/gazebo/xmlschema/#sensor"
       xmlns:controller="http://playerstage.sourceforge.net/gazebo/xmlschema/#controller"
       xmlns:interface="http://playerstage.sourceforge.net/gazebo/xmlschema/#interface"
       xmlns:xacro="http://ros.org/wiki/xacro">

  <include filename="$(find cob_description)/ros/urdf/headeyes_v0/headeyes.gazebo.xacro" />
  <include filename="$(find cob_description)/ros/urdf/headeyes_v0/headeyes.transmission.xacro" />
  <include filename="$(find cob_description)/ros/urdf/sensors/cameraone.urdf.xacro" /> 

<!--####################################################################-->
                       <!--Fix Some Parameters Later-->
<!--####################################################################-->
  <xacro:macro name="cob_headeyes_v0" params="name parent *origin">
    
    <!--joint between torso_headbase_link and headeye_base_link-->
    <joint name="${name}_base_joint" type="revolute">
       <insert_block name="origin" />
       <parent link="${parent}"/>
       <child link="${name}_base_link"/>
       <axis xyz="0 0 1" />
       <dynamics damping="0.1" />
       <calibration reference_position="-3.14"/>
       <limit effort="100" lower="-0.1745" upper="3.316" velocity="0.5"/> 
    </joint>
   
    <link name="${name}_base_link">
       <inertial>
	  <origin xyz="0 0 0" rpy="0 0 0"/>
	  <mass value="0.1"/>
	  <inertia ixx="0.0001"  ixy="0"  ixz="0" iyy="0.0001" iyz="0" izz="0.0001" />
       </inertial>

       <visual>
	 <origin xyz="0 0 0" rpy="0 0 0" />
	 <geometry>
	    <box size="0.1 0.1 0.01"/>
	 </geometry>
         <material name="Green" />
       </visual>

       <collision>
	 <origin xyz="0 0 0" rpy="0 0 0" />
	 <geometry>
            <box size="0.1 0.1 0.01"/>
	 </geometry>
       </collision>
    </link>

    <!--joint between headeyes_base_link and headeyes_left_link-->
    <joint name="${name}_left_joint" type="fixed">
       <origin xyz="0 0.05 0" rpy="0 0 0" />
       <parent link="${name}_base_link"/>
       <child link="${name}_left_link"/>
    </joint>
   
    <link name="${name}_left_link">
       <inertial>
	  <origin xyz="0 0 0" rpy="0 0 0"/>
	  <mass value="0.01"/>
	  <inertia ixx="0.0001"  ixy="0"  ixz="0" iyy="0.0001" iyz="0" izz="0.0001" />
       </inertial>

       <visual>
	 <origin xyz="0 0 0" rpy="0 0 0" />
	 <geometry>
	    <box size="0.01 0.01 0.01"/>
	 </geometry>
         <material name="Red" />
       </visual>

       <collision>
	 <origin xyz="0 0 0" rpy="0 0 0" />
	 <geometry>
            <box size="0.01 0.01 0.01"/>
	 </geometry>
       </collision>
    </link>

    <!--joint between headeyes_base_link and headeyes_right_link-->
    <joint name="${name}_right_joint" type="fixed">
       <origin xyz="0 -0.05 0" rpy="0 0 0" />
       <parent link="${name}_base_link"/>
       <child link="${name}_right_link"/>
    </joint>
   
    <link name="${name}_right_link">
       <inertial>
	  <origin xyz="0 0 0" rpy="0 0 0"/>
	  <mass value="0.01"/>
	  <inertia ixx="0.0001"  ixy="0"  ixz="0" iyy="0.0001" iyz="0" izz="0.0001" />
       </inertial>

       <visual>
	 <origin xyz="0 0 0" rpy="0 0 0" />
	 <geometry>
	    <box size="0.01 0.01 0.01"/>
	 </geometry>
         <material name="Red" />
       </visual>

       <collision>
	 <origin xyz="0 0 0" rpy="0 0 0" />
	 <geometry>
            <box size="0.01 0.01 0.01"/>
	 </geometry>
       </collision>
    </link>

    <!--joint between headeyes_base_link and headeyes_swissranger_link-->
    <joint name="${name}_swissranger_joint" type="fixed">
       <origin xyz="0 0 0" rpy="0 0 0" />
       <parent link="${name}_base_link"/>
       <child link="${name}_swissranger_link"/>
    </joint>
   
    <link name="${name}_swissranger_link">
       <inertial>
	  <origin xyz="0 0 0" rpy="0 0 0"/>
	  <mass value="0.01"/>
	  <inertia ixx="0.0001"  ixy="0"  ixz="0" iyy="0.0001" iyz="0" izz="0.0001" />
       </inertial>

       <visual>
	 <origin xyz="0 0 0" rpy="0 0 0" />
	 <geometry>
	    <box size="0.01 0.01 0.01"/>
	 </geometry>
         <material name="Blue" />
       </visual>

       <collision>
	 <origin xyz="0 0 0" rpy="0 0 0" />
	 <geometry>
            <box size="0.01 0.01 0.01"/>
	 </geometry>
       </collision>
    </link>

    <!--##################################################-->
    <!-- camera test here -->
    <xacro:cob_cameraone_v0 name="camera_left" parent="headeyes_left_link">
      <origin xyz="0 0 0" rpy="0 0 0" />
    </xacro:cob_cameraone_v0>

    <xacro:cob_cameraone_v0 name="camera_right" parent="headeyes_right_link">
      <origin xyz="0 0 0" rpy="0 0 0" />
    </xacro:cob_cameraone_v0>

    <!-- extensions -->
    <xacro:cob_headeyes_gazebo_v0 name="${name}" />
    <xacro:cob_headeyes_transmission_v0 name="${name}" />


  </xacro:macro>

</robot>


