<?xml version="1.0"?>
<robot xmlns:xacro="http://www.ros.org/wiki/xacro">

  <xacro:include filename="$(find cob_description)/urdf/ur_connector/ur_connector.gazebo.xacro" />
  <xacro:include filename="$(find cob_description)/urdf/ur_connector/ur_connector.transmission.xacro" />

  <xacro:macro name="ur_connector" params="name parent *origin">

    <!-- joint between base_link and ur_connector_link -->
    <joint name="${name}_fixed_joint" type="fixed">
      <insert_block name="origin" />
      <parent link="${parent}"/>
      <child link="${name}_fixed_link"/>
    </joint>

    <link name="${name}_fixed_link">
      <inertial>
        <origin xyz="0 0 0" rpy="0 0 0"/>
        <mass value="2"/>
        <inertia ixx="0.01" ixy="0" ixz="0" iyy="0.01" iyz="0" izz="0.01" />
      </inertial>

      <visual>
        <origin xyz="0 0 0" rpy="0 0 0" />
        <geometry>
          <mesh filename="package://cob_description/meshes/ur_connector/ur_connector1.stl" />
        </geometry>
        <material name="IPA/DarkGrey" />
      </visual>

      <collision>
        <origin xyz="0 0 0" rpy="0 0 0" />
        <geometry>
          <mesh filename="package://cob_description/meshes/ur_connector/ur_connector1.stl" />
        </geometry>
      </collision>
    </link>

    <!-- joint between base_link and ur_connector_link -->
    <joint name="${name}_joint" type="revolute">
      <origin xyz="-0.0201 -0.1736 0.136" rpy="0 0 0"/>
      <parent link="${name}_fixed_link"/>
      <child link="${name}_link"/>
      <axis xyz="0 0 1"/>
      <dynamics damping="10"/>
      <limit effort="200" velocity="1.9634" lower="1.0" upper="4.6"/>
      <safety_controller k_position="20" k_velocity="50" soft_lower_limit="${1.0 - 0.01}" soft_upper_limit="${4.6 - 0.01}" />
    </joint>

    <link name="${name}_link">
      <inertial>
        <origin xyz="0 0 0" rpy="0 0 0"/>
        <mass value="1"/>
        <inertia ixx="0.01" ixy="0" ixz="0" iyy="0.01" iyz="0" izz="0.01" />
      </inertial>

      <visual>
        <origin xyz="0 0 0" rpy="0 0 0" />
        <geometry>
          <mesh filename="package://cob_description/meshes/ur_connector/ur_connector2.stl" />
        </geometry>
        <material name="IPA/DarkGrey" />
      </visual>

      <collision>
        <origin xyz="0 0 0" rpy="0 0 0" />
        <geometry>
          <mesh filename="package://cob_description/meshes/ur_connector/ur_connector2.stl" />
        </geometry>
      </collision>
    </link>

    <!-- extensions -->
    <xacro:ur_connector_gazebo name="${name}" />
    <xacro:ur_connector_transmission name="${name}" />

  </xacro:macro>
  
</robot>
