<?xml version="1.0"?>
<robot xmlns:sensor="http://playerstage.sourceforge.net/gazebo/xmlschema/#sensor"
       xmlns:controller="http://playerstage.sourceforge.net/gazebo/xmlschema/#controller"
       xmlns:interface="http://playerstage.sourceforge.net/gazebo/xmlschema/#interface"
       xmlns:xacro="http://ros.org/wiki/xacro">

	<include filename="$(find raw_description)/urdf/torso/torso.gazebo.xacro" />
	<include filename="$(find raw_description)/urdf/torso/torso.transmission.xacro" />

	<include filename="$(find cob_description)/urdf/sensors/prosilica.urdf.xacro" />
	<include filename="$(find cob_description)/urdf/sensors/kinect.urdf.xacro" />

	<xacro:macro name="raw_torso" params="name parent *origin">

        
		<!-- joint between base_link and torso_tilt_link -->
		<joint name="${name}_0_joint" type="fixed" >
			<insert_block name="origin" />
			<parent link="${parent}" />
			<child link="${name}_0_link" />
		</joint>


		<link name="${name}_0_link">
			<inertial>
				<origin xyz="0 0 0" rpy="0 0 0"/>
				<mass value="0.57307"/>
				<inertia ixx="1.415" ixy="0" ixz="0" iyy="0.819" iyz="0" izz="0.819" />
			</inertial>

			<visual>
				<origin xyz="0 0 -0.26" rpy="0 0 0" /> 
				<geometry>
					<cylinder length="0.521" radius="0.04"/>
				</geometry>
				<material name="Grey" />
			</visual>

			<collision>
				<origin xyz="0 0 -0.26" rpy="0 0 0" /> 
				<geometry>
					<cylinder length="0.521" radius="0.04"/>
				</geometry>
			</collision>
		</link> 

		<!-- joint between base_link and torso_lower_neck_tilt_link -->
		<joint name="${name}_tilt_joint" type="revolute">
			<origin xyz="0.0 0.0 0.3074" rpy="0.0 0.0 -0.48" />
			<parent link="${name}_0_link"/>
			<child link="${name}_tilt_link"/>
			<axis xyz="0 0 -1.0" />
			<dynamics damping="25.0" friction="10.0"/>
			<calibration rising="0.0"/>
			<limit effort="41.4" lower="-6.2831" upper="6.2831" velocity="0.5"/>
		</joint>

		<link name="${name}_tilt_link">
			<inertial>
				<origin xyz="0 0 0" rpy="0 0 0"/>
				<mass value="6.209720"/>
				<inertia ixx="0.171118" ixy="0.002544" ixz="-0.000000" iyy="0.083077" iyz="0.000000" izz="0.120948" />
			</inertial>

			<visual>
				<origin xyz="0 0 0" rpy="3.14 0 0" />
				<geometry>
					<cylinder length="0.1" radius="0.1"/>
				</geometry>
				<material name="Red" />
			</visual>

			<collision>
				<origin xyz="0 0 0" rpy="3.14 0 0" />
				<geometry>
					<cylinder length="0.1" radius="0.1"/>
				</geometry>
			</collision>
		</link>

		<!-- joint between torso_upper_neck_tilt_link and head_axis_link -->
		<joint name="head_axis_joint" type="revolute">
			<origin xyz="0.0 0.0 0.047" rpy="0.0 0.0 0.0" />
   			<parent link="${name}_tilt_link"/>
			<child link="head_axis_link"/>
			<axis xyz="0 0 -1.0" />
			<dynamics damping="0.1" />
			<calibration rising="0.0"/>
			<limit effort="100" lower="-3.2" upper="0.1" velocity="1.4"/>
		</joint>

		<link name="head_axis_link">
			<inertial>
				<origin xyz="0 0 0" rpy="0 0 0"/>
				<mass value="0.1"/>
				<inertia ixx="0.0001" ixy="0" ixz="0" iyy="0.0001" iyz="0" izz="0.0001" />
			</inertial>

			<visual>
				<origin xyz="0 0 0" rpy="0 0 0" />
				<geometry>
					<box size="0.01 0.01 0.01"/>
				</geometry>
				<material name="Green" />
			</visual>

			<collision>
				<origin xyz="0 0 0" rpy="0 0 0" />
				<geometry>
					<box size="0.01 0.01 0.01"/>
				</geometry>
			</collision>
		</link>

		<!-- left camera -->
		<xacro:cob_prosilica_v0 name="head_color_camera_l" ros_topic="stereo/left" parent="head_axis_link">
			<origin xyz="${cam_l_x} ${cam_l_y} ${cam_l_z}" rpy="${cam_l_roll} ${cam_l_pitch} ${cam_l_yaw}" />
		</xacro:cob_prosilica_v0>

		<!-- right camera -->
		<xacro:cob_prosilica_v0 name="head_color_camera_r" ros_topic="stereo/right" parent="head_axis_link">
			<origin xyz="${cam_r_x} ${cam_r_y} ${cam_r_z}" rpy="${cam_r_roll} ${cam_r_pitch} ${cam_r_yaw}" />
		</xacro:cob_prosilica_v0>

		<!-- cam3d -->
		<xacro:cob_kinect_v0 name="head_cam3d" ros_topic="cam3d" parent="head_axis_link">
			<origin xyz="${cam3d_x} ${cam3d_y} ${cam3d_z}" rpy="${cam3d_roll} ${cam3d_pitch} ${cam3d_yaw}" />
		</xacro:cob_kinect_v0>

		<!-- extensions -->
		<xacro:raw_torso_gazebo name="${name}" />
		<xacro:raw_torso_transmission name="${name}" />

	</xacro:macro>
	
</robot>
