<?xml version="1.0"?>
<robot xmlns:xacro="http://www.ros.org/wiki/xacro">

  <xacro:include filename="$(find raw_description)/urdf/torso/torso.gazebo.xacro" />
  <xacro:include filename="$(find raw_description)/urdf/torso/torso.transmission.xacro" />

  <xacro:macro name="raw_torso" params="name parent *origin">
    
    <!-- joint between base_link and torso_tilt_link -->
    <joint name="${name}_0_joint" type="fixed" >
      <insert_block name="origin" />
      <parent link="${parent}" />
      <child link="${name}_0_link" />
    </joint>
    
    <link name="${name}_0_link">
      <inertial>
        <origin xyz="0 0 0" rpy="0 0 0"/>
        <mass value="0.57307"/>
        <inertia ixx="1.415" ixy="0" ixz="0" iyy="0.819" iyz="0" izz="0.819" />
      </inertial>
      
      <visual>
        <origin xyz="0 0 0" rpy="0 0 0" /> 
        <geometry>
          <cylinder length="0.521" radius="0.04"/>
        </geometry>
        <material name="IPA/LightGrey" />
      </visual>

      <collision>
        <origin xyz="0 0 0" rpy="0 0 0" />
        <geometry>
          <cylinder length="0.521" radius="0.04"/>
        </geometry>
      </collision>
    </link> 

    <!-- joint between base_link and torso_lower_neck_tilt_link -->
    <joint name="${name}_pan_joint" type="revolute">
      <origin xyz="0.0 0.0 0.3074" rpy="0.0 0.0 0.0" />
      <parent link="${name}_0_link"/>
      <child link="${name}_1_link"/>
      <axis xyz="0 0 -1.0" />
      <dynamics damping="25.0" friction="10.0"/>
      <calibration rising="${torso_pan_ref}"/>
      <limit effort="41.4" lower="-6.2831" upper="6.2831" velocity="0.5"/>
    </joint>

    <link name="${name}_1_link">
      <inertial>
        <origin xyz="0 0 0" rpy="0 0 0"/>
        <mass value="6.209720"/>
        <inertia ixx="0.171118" ixy="0.002544" ixz="-0.000000" iyy="0.083077" iyz="0.000000" izz="0.120948" />
      </inertial>

      <visual>
        <origin xyz="0 0 0" rpy="3.14 0 0" />
        <geometry>
          <cylinder length="0.3" radius="0.15"/>
        </geometry>
        <material name="IPA/LightGrey" />
      </visual>

      <collision>
        <origin xyz="0 0 0" rpy="3.14 0 0" />
        <geometry>
          <cylinder length="0.3" radius="0.15"/>
        </geometry>
      </collision>
    </link>

    <!-- joint between torso_upper_neck_tilt_link and head_axis_link -->
    <joint name="torso_tilt_joint" type="revolute">
      <origin xyz="0.0 0.0 0.047" rpy="0.0 0.0 0.0" />
         <parent link="${name}_1_link"/>
      <child link="torso_2_link"/>
      <axis xyz="0 1.0 0" />
      <dynamics damping="0.1" />
      <calibration rising="${torso_tilt_ref}"/>
      <limit effort="100" lower="-3.2" upper="1.57" velocity="1.4"/>
    </joint>

    <link name="torso_2_link">
      <inertial>
        <origin xyz="0 0 0" rpy="0 0 0"/>
        <mass value="0.1"/>
        <inertia ixx="0.0001" ixy="0" ixz="0" iyy="0.0001" iyz="0" izz="0.0001" />
      </inertial>

      <visual>
        <origin xyz="0 0 0" rpy="0 0 0" />
        <geometry>
          <box size="0.01 0.01 0.01"/>
        </geometry>
        <material name="IPA/LightGrey" />
      </visual>

      <collision>
        <origin xyz="0 0 0" rpy="0 0 0" />
        <geometry>
          <box size="0.01 0.01 0.01"/>
        </geometry>
      </collision>
    </link>

    <!-- extensions -->
    <xacro:raw_torso_gazebo name="${name}" />
    <xacro:raw_torso_transmission name="${name}" />

  </xacro:macro>
  
</robot>
