<?xml version="1.0"?>
<robot xmlns:xacro="http://www.ros.org/wiki/xacro">

  <xacro:include filename="$(find raw_description)/urdf/powerball/powerball_ERB115.gazebo.xacro" />
  <xacro:include filename="$(find raw_description)/urdf/powerball/powerball_ERB115.transmission.xacro" />

  <xacro:macro name="powerball_ERB115" params="parent name *origin">

    <joint name="${name}_base_joint" type="fixed" >
      <xacro:insert_block name="origin" />
      <parent link="${parent}" />
      <child link="${name}_base_link" />
    </joint>

    <link name="${name}_base_link">
      <inertial>
        <origin xyz="0 0 0" rpy="0 0 0"/>
        <mass value="0.01"/>
        <inertia ixx="0.01" ixy="0" ixz="0" iyy="0.01" iyz="0" izz="0.01" />
      </inertial>
    </link>
  
    <!-- joint between base_link and powerball_link -->
    <joint name="${name}_bottom_joint" type="revolute" >
      <origin xyz="0 0 0" rpy="0 0 0"/>f
      <parent link="${name}_base_link" />
      <child link="${name}_ball_link" />
      <axis xyz="0 0 1" />
      <dynamics damping="6" />
      <limit effort="41.6" velocity="2.0" lower="-3.1415" upper="3.1415" />
      <safety_controller k_position="20" k_velocity="25" soft_lower_limit="${-3.1415 + 0.01}" soft_upper_limit="${3.1415 - 0.01}" />

    </joint>

    <link name="${name}_ball_link">
      <inertial>
        <origin xyz="0 0 0" rpy="0 0 0"/>
        <mass value="1"/>
        <inertia ixx="0.03" ixy="0" ixz="0" iyy="0.03" iyz="0" izz="0.03" />
      </inertial>

      <visual>
        <origin xyz="0 0 0" rpy="0 0 0" />
        <geometry>
          <mesh filename="package://raw_description/meshes/powerball/ERB115_ball.dae" />
        </geometry>
      </visual>

      <collision>
        <origin xyz="0 0 0" rpy="0 0 0" />
        <geometry>
          <mesh filename="package://raw_description/meshes/powerball/ERB115_ball_scaled.stl" />
        </geometry>
      </collision>
    </link>

    <!-- joint between _powerball_ball_link and _powerball_knob_link -->
    <joint name="${name}_side_joint" type="revolute" >
      <origin xyz="0 0 0" rpy="-1.5708 0 0" />
      <parent link="${name}_ball_link" />
      <child link="${name}_knob_link" />
      <axis xyz="0 0 1" />
      <dynamics damping="6" />
      <limit effort="20.1" velocity="2.0" lower="-2.0943951" upper="2.0943951" />
      <safety_controller k_position="20" k_velocity="25" soft_lower_limit="${-2.0943951 + 0.01}" soft_upper_limit="${2.0943951 - 0.01}" />
    </joint>

    <link name="${name}_knob_link">
      <inertial>
        <origin xyz="0 0 0" rpy="0 0 0"/>
        <mass value="0.819"/>
        <inertia ixx="0.01" ixy="0" ixz="0" iyy="0.01" iyz="0" izz="0.01" />
      </inertial>

      <visual>
        <origin xyz="0 0 0" rpy="0 0 0" />
        <geometry>
          <mesh filename="package://raw_description/meshes/powerball/ERB115_knob.dae" />
        </geometry>
      </visual>

      <collision>
        <origin xyz="0 0 0" rpy="0 0 0" />
        <geometry>
          <mesh filename="package://raw_description/meshes/powerball/ERB115_knob.stl" />
        </geometry>
      </collision>
    </link>

    <xacro:powerball_ERB115_gazebo name="${name}" />
    <xacro:powerball_ERB115_transmission name="${name}" />

  </xacro:macro>

</robot>
