<?xml version="1.0"?>
<robot xmlns:xacro="http://www.ros.org/wiki/xacro">

  <xacro:macro name="lookat" params="name parent *origin *axis lower upper">
  
    <!-- joint between torso_upper_neck_tilt_link and lookat_base_link -->
    <joint name="${name}_base_joint" type="fixed">
      <insert_block name="origin" />
      <parent link="${parent}"/>
      <child link="${name}_base_link"/>
    </joint>
  
    <link name="${name}_base_link"/>
    
    <joint name="${name}_lin_joint" type="prismatic">
      <origin xyz="0 0 0" rpy="0 0 0" />
      <parent link="${name}_base_link"/>
      <child link="${name}_x_link"/>
      <insert_block name="axis" />  <!--axis xyz="-1 0 0" /-->
      <dynamics damping="5.0" friction="0.5"/>
      <limit effort="100" lower="${lower}" upper="${upper}" velocity="1"/>    
    </joint>
    
    <link name="${name}_x_link"/>
    
    <joint name="${name}_x_joint" type="revolute">
      <origin xyz="0 0 0" rpy="0 0 0" />
      <parent link="${name}_x_link"/>
      <child link="${name}_y_link"/>
      <axis xyz="1 0 0" />
      <dynamics damping="5.0" friction="0.5"/>
      <limit effort="100" lower="-${M_PI}" upper="${M_PI}" velocity="1"/>    
    </joint>
    
    <link name="${name}_y_link"/>
    
    <joint name="${name}_y_joint" type="revolute">
      <origin xyz="0 0 0" rpy="0 0 0" />
      <parent link="${name}_y_link"/>
      <child link="${name}_z_link"/>
      <axis xyz="0 1 0" />
      <dynamics damping="5.0" friction="0.5"/>
      <limit effort="100" lower="-${M_PI}" upper="${M_PI}" velocity="1"/>    
    </joint>
    
    <link name="${name}_z_link"/>
    
    <joint name="${name}_z_joint" type="revolute">
      <origin xyz="0 0 0" rpy="0 0 0" />
      <parent link="${name}_z_link"/>
      <child link="${name}_focus_frame"/>
      <axis xyz="0 0 1" />
      <dynamics damping="5.0" friction="0.5"/>
      <limit effort="100" lower="-${M_PI}" upper="${M_PI}" velocity="1"/>    
    </joint>
    
    <link name="${name}_focus_frame">
<!--
      <visual>
        <origin xyz="0 0 0" rpy="0 0 0" />
        <geometry>
          <box size="0.05 0.05 0.2"/>
        </geometry>
        <material name="IPA/Black" />
      </visual>
-->
    </link>

  </xacro:macro>

</robot>
