<?xml version="1.0"?>
<robot xmlns:xacro="http://www.ros.org/wiki/xacro">

  <xacro:include filename="$(find cob_description)/urdf/cob4_head/head.gazebo.xacro" />
  <xacro:include filename="$(find cob_description)/urdf/cob4_head/head.transmission.xacro" />

  <xacro:macro name="head" params="parent name *origin">

    <joint name="head_base_joint" type="fixed">
      <insert_block name="origin" />
      <child link="head_base_link" />
      <parent link="${parent}"/>
    </joint>
    
    <link name="head_base_link">
      <inertial>
        <origin xyz="0 0 0" rpy="0 0 0"/>
        <mass value="0.1"/>
        <inertia ixx="0.01" ixy="0" ixz="0" iyy="0.01" iyz="0" izz="0.01" />
      </inertial>
    </link>

    <joint name="head_1_joint" type="revolute">
      <origin xyz="0 0 0.0305" rpy="0 0 0"/>
      <child link="head_1_link" />
      <parent link="head_base_link"/>
      <calibration rising="${head_1_ref}"/>
      <axis xyz="0 0 1" />
      <dynamics damping="0.1" />
      <limit effort="100" lower="-6.2831" upper="6.2831" velocity="1.4"/>
    </joint>

    <link name="head_1_link">
      <inertial>
        <origin xyz="0 0 0" rpy="0 0 0"/>
        <mass value="0.1"/>
        <inertia ixx="0.01" ixy="0" ixz="0" iyy="0.01" iyz="0" izz="0.01" />
      </inertial>
    </link>

    <joint name="head_2_joint" type="revolute">
      <origin xyz="0 -0.07725 -0.00439" rpy="-0.349 0 0" />
      <child link="head_2_link" />
      <parent link="head_1_link"/>
      <calibration rising="${head_2_ref}"/>
      <axis xyz="0 0 1" />
      <dynamics damping="0.1" />
      <limit effort="100" lower="-6.2831" upper="6.2831" velocity="1.4"/>
    </joint>

    <link name="head_2_link">
      <inertial>
        <origin xyz="0 0 0" rpy="0 0 0"/>
        <mass value="0.1"/>
        <inertia ixx="0.01" ixy="0" ixz="0" iyy="0.01" iyz="0" izz="0.01" />
      </inertial>
    </link>


    <joint name="head_3_joint" type="revolute">
      <origin xyz="0 0.04668 0.0976" rpy="0.349 0 0" />
      <child link="head_3_link" />
      <parent link="head_2_link"/>
      <calibration rising="${head_3_ref}"/>
      <axis xyz="0 0 1" />
      <dynamics damping="0.1" />
      <limit effort="100" lower="-6.2831" upper="6.2831" velocity="1.4"/>
    </joint>

    <link name="head_3_link">
      <inertial>
      <mass value="1" />
      <origin xyz="0 0 0" />
      <inertia ixx="0.01" ixy="0" ixz="0" iyy="0.01" iyz="0" izz="0.01" />
      </inertial>

      <visual>
      <origin xyz="0 0 0" rpy="0 0 0" />  
      <geometry>
        <mesh filename="package://cob_description/meshes/cob4_head/head_link.stl"/>
      </geometry> 
      <material name="IPA/LightGrey"/>
      </visual>

      <collision>
      <origin xyz="0 0 0" rpy="0 0 0" />
      <geometry>
        <box size="0.001 0.001 0.001" />
      </geometry>
      </collision>
    </link>

  <!-- extensions -->
  <xacro:head_gazebo name="${name}" />
  <xacro:head_transmission name="${name}" />

  </xacro:macro>

</robot>
