<?xml version="1.0"?>
<robot xmlns:sensor="http://playerstage.sourceforge.net/gazebo/xmlschema/#sensor"
       xmlns:controller="http://playerstage.sourceforge.net/gazebo/xmlschema/#controller"
       xmlns:interface="http://playerstage.sourceforge.net/gazebo/xmlschema/#interface"
       xmlns:xacro="http://ros.org/wiki/xacro">

  <include filename="$(find cob_description)/ros/urdf/base_v0/base.gazebo.xacro" />
  <include filename="$(find cob_description)/ros/urdf/base_v0/base.transmission.xacro" />
  
  <!-- modify here for test -->
  <include filename="$(find cob_description)/ros/urdf/sensors/hokuyo_lx30_laser.urdf.xacro"/>

  <!-- DATA SOURCES -->
  <!-- all link offsets, CG, limits are obtained from Function Engineering spreadsheet 090224_link_data.xls unless stated otherwise -->
  <!-- all link geometry sizes are obtained from Function provided CAD model unless stated otherwise -->
  <!-- all simplified collision geometry are hand approximated from CAD model, sometimes from respective bounding boxes -->

  <property name="M_PI" value="3.1415926535897931" />

  <property name="caster_offset_x" value="0.235" />  <!--modify here-->
  <property name="caster_offset_y" value="0.185" />
  <property name="caster_offset_z" value="0.0282" />

  <property name="caster_wheel_offset_y" value="0.049" />
  <property name="wheel_length" value="0.034" />
  <property name="wheel_radius" value="0.074792" />   <!-- This is the 'effective' wheel radius. Wheel radius for uncompressed wheel is 0.079.  mp 20080801 -->

  <property name="base_cg_x" value="-0.061" />
  <property name="base_cg_y" value="0.0" />
  <property name="base_cg_z" value="0.293" />
  <property name="base_mass" value="116.0" />

  <!-- simplified box collision geometry for base -->
  <property name="base_size_x" value="0.8" />
  <property name="base_size_y" value="0.6" />
  <property name="base_size_z" value="0.23" />
  <property name="base_collision_size_z" value="0.04" />

  <!-- simplified box collision geometry for hokuyo laser -->
  <property name="base_laser_x" value="0.325" />
  <property name="base_laser_y" value="0.0" />
  <property name="base_laser_z" value="0.135" />
  <property name="base_laser_size_x" value="0.06" />
  <property name="base_laser_size_y" value="0.06" />
  <property name="base_laser_size_z" value="0.03" />
  <property name="base_laser_collision_offset_z" value="0.023" />

  <!--                                                      -->
  <!--           wheel                                      -->
  <!--                                                      -->
  <xacro:macro name="cob_wheel_v0" params="suffix parent reflect">

    <joint name="${parent}_${suffix}_wheel_joint" type="continuous">
      <axis xyz="0 1 0" />
      <limit effort="100" velocity="100"/> <!-- alpha tested effort and velocity limits -->
      <safety_controller  k_velocity="10" />
      <dynamics damping="0.0" friction="0.0" />
      <origin xyz="0 ${reflect*caster_wheel_offset_y} 0" rpy="0 0 0" />
      <parent link="${parent}_rotation_link"/>
      <child link="${parent}_${suffix}_wheel_link"/>
    </joint>

    <link name="${parent}_${suffix}_wheel_link">
      <inertial>
        <mass value="0.44036" />
        <origin xyz="0 0 0" />
        <inertia  ixx="0.012411765597" ixy="-0.000711733678" ixz="0.00050272983"
                  iyy="0.015218160428" iyz="-0.000004273467" izz="0.011763977943" />
      </inertial>
      <visual>
        <origin xyz="0 0 0" rpy="0 0 0" />
        <geometry>
          <mesh filename="package://cob_description/ros/meshes/base_v0/pr2_wheel.stl" />
          <!--cylinder radius="${wheel_radius}" length="${wheel_length}" /-->
        </geometry>
        
        <material name="Wheel_${suffix}" />
      </visual>
      <collision>
        <origin xyz="0 0 0" rpy="${M_PI/2} 0 0" /> <!-- rotation because cyl. geom primitive has symmetry axis in +x direction -->
        <geometry>
          <cylinder radius="${wheel_radius}" length="${wheel_length}" />
        </geometry>
      </collision>
    </link>

    <!-- extensions -->
    <xacro:cob_wheel_gazebo_v0 parent="${parent}" suffix="${suffix}" />
    <xacro:cob_wheel_transmission_v0 parent="${parent}" suffix="${suffix}" reflect="${reflect}" />

  </xacro:macro>

  <!-- Macro for Caster hub only -->
  <xacro:macro name="cob_drive_v0" params="suffix parent *origin ref_position" >
    <joint name="${suffix}_rotation_joint" type="continuous">
      <axis xyz="0 0 1" />
      <limit effort="100" velocity="100"/> <!-- alpha tested velocity and effort limits -->
      <safety_controller  k_velocity="10" />
      <calibration rising="${ref_position}" falling="${ref_position}" />
      <dynamics damping="0.0" friction="0.0" />
      <insert_block name="origin" />
      <parent link="${parent}"/>
      <child link="${suffix}_rotation_link" />
    </joint>
    <link name="${suffix}_rotation_link">

      <inertial>
        <mass value="3.473082"/>
        <origin xyz="0 0 0.1" />
        <inertia  ixx="0.012411765597" ixy="-0.000711733678" ixz="0.00050272983"
                  iyy="0.015218160428" iyz="-0.000004273467" izz="0.011763977943" />
      </inertial>

      <visual>
        <origin xyz="0 0 0.1" rpy="0 0 0" />
        <geometry>
          <!--mesh filename="package://cob_description/ros/meshes/base_v0/caster.stl" /-->
          <box size="0.1 0.05 0.2" />
        </geometry>
    
        <material name="Green" />
      </visual>

      <collision>
        <origin xyz="0 0 0.1" rpy="0.0 0.0 0.0" />
        <geometry>
          <!--mesh filename="package://cob_description/ros/meshes/base_v0/caster.stl" /-->
          <box size="0.1 0.05 0.2" />
        </geometry>
      </collision>
    </link>

    <!-- extensions -->
    <xacro:cob_caster_transmission_v0 suffix="${suffix}" />
  </xacro:macro>

  <xacro:macro name="cob_caster_v0" params="suffix parent *origin ref_position">

    <xacro:cob_drive_v0 parent="${parent}" suffix="${suffix}_caster"
                             ref_position="${ref_position}" >
      <insert_block name="origin" />
    </xacro:cob_drive_v0>

    <!-- wheel macros -->
    <xacro:cob_wheel_v0 parent="${suffix}_caster" suffix="l" reflect="1" />

    <!-- extensions -->
    <xacro:cob_caster_gazebo_v0 suffix="${suffix}" />
  </xacro:macro>


  <!-- The xacro macro xacro:cob_base contains: base, casters and wheels -->
  <xacro:macro name="cob_base_v0" params="name">
  <link name="${name}_link">

      <inertial>
        <mass value="30" />
        <origin xyz="0 0 0" />
        <inertia ixx="5.652232699207" ixy="-0.009719934438" ixz="1.293988226423"
                 iyy="5.669473158652" iyz="-0.007379583694" izz="3.683196351726" />
      </inertial>

      <visual>
        <origin xyz="0 0 0" rpy="0 0 0" />  
        <!-- modify here for test-->
        <geometry>
          <mesh filename="package://cob_defs/common/files/meshes/platform.stl"/>
          <!--box size="0.6 0.8 0.1" /-->
        </geometry> 
        <material name="Grey"/>
      </visual>

      <collision>
        <!-- represent base collision with a simple rectangular model, positioned by base_size_z s.t. top
             surface of the collision box matches the top surface of the PR2 base -->
        <origin xyz="0 0 0" rpy="0 0 0" />
        <geometry>
          <!--mesh filename="package://cob_defs/common/files/meshes/platform.stl"/-->
          <box size="0.6 0.8 0.1" />
        </geometry>
      </collision>
    </link>

    <!-- base_footprint is a fictitious link(frame) that is on the ground right below base_link origin,
         navigation stack dedpends on this frame -->
    <link name="${name}_footprint">
      <inertial>
        <mass value="1.0" />
        <origin xyz="0 0 0" />
        <inertia ixx="0.01" ixy="0.0" ixz="0.0"
                 iyy="0.01" iyz="0.0" izz="0.01" />
      </inertial>
      <visual>
        <origin xyz="0 0 0" rpy="0 0 0" />
        <geometry>
          <box size="0.01 0.01 0.01" />
        </geometry>
        
        <material name="Red" />
      </visual>
      <collision>

        <!-- represent base collision with a simple rectangular model, positioned by base_size_z s.t. top
             surface of the collision box matches the top surface of the PR2 base -->
        <origin xyz="0 0 0" rpy="0 0 0" />
        <geometry>
          <box size="0.01 0.01 0.01" />
        </geometry>
      </collision>
    </link>

    <joint name="${name}_footprint_joint" type="fixed">
      <origin xyz="0 0 0.15" rpy="0 0 0" />
      <child link="${name}_link" />
      <parent link="${name}_footprint"/>
    </joint>

    <!--modify here for test: front,base and top lasers -->
    <!-- base laser front -->
    <xacro:hokuyo_lx30_laser_v0 name="${name}_laser_front" parent="${name}" ros_topic="scan_front" update_rate="20" min_angle="-1.35" max_angle="1.35" >
      <origin xyz="${base_laser_x} ${base_laser_y} ${base_laser_z}" rpy="0 0 0" />
    </xacro:hokuyo_lx30_laser_v0>

    <!-- base laser rear -->
    <xacro:hokuyo_lx30_laser_v0 name="${name}_laser_rear" parent="${name}" ros_topic="scan_rear" update_rate="20" min_angle="-1.35" max_angle="1.35" >
      <origin xyz="${-base_laser_x} ${base_laser_y} ${base_laser_z}" rpy="0 0 ${M_PI}" />
    </xacro:hokuyo_lx30_laser_v0>

    <!-- base laser top -->
    <xacro:hokuyo_lx30_laser_v0 name="${name}_laser_top" parent="${name}" ros_topic="scan_top" update_rate="10" min_angle="-2.094" max_angle="2.094" >
      <origin xyz="-0.252 0 0.42" rpy="0 0 ${M_PI}" />
    </xacro:hokuyo_lx30_laser_v0>

    <!-- all four caster macros -->
    <xacro:cob_caster_v0 suffix="fl" parent="${name}_link" ref_position="${cal_caster_fl - M_PI/4}" >
      <origin xyz="${caster_offset_x} ${caster_offset_y} ${caster_offset_z}" rpy="0 0 0" />
    </xacro:cob_caster_v0>
    <xacro:cob_caster_v0 suffix="fr" parent="${name}_link" ref_position="${cal_caster_fr - M_PI/4}" >
      <origin xyz="${caster_offset_x} ${-caster_offset_y} ${caster_offset_z}" rpy="0 0 0" />
    </xacro:cob_caster_v0>
    <xacro:cob_caster_v0 suffix="bl" parent="${name}_link" ref_position="${cal_caster_bl - M_PI / 4 + M_PI}" >
      <origin xyz="${-caster_offset_x} ${caster_offset_y} ${caster_offset_z}" rpy="0 0 0" />
    </xacro:cob_caster_v0>
    <xacro:cob_caster_v0 suffix="br" parent="${name}_link" ref_position="${cal_caster_br - M_PI / 4 + M_PI}"  >
      <origin xyz="${-caster_offset_x} ${-caster_offset_y} ${caster_offset_z}" rpy="0 0 0" />
    </xacro:cob_caster_v0>

    <!-- gazebo extensions -->
    <xacro:cob_base_gazebo_v0 name="${name}" />

  </xacro:macro>


</robot>
