<?xml version="1.0"?>
<robot  xmlns:sensor="http://playerstage.sourceforge.net/gazebo/xmlschema/#sensor"
	xmlns:controller="http://playerstage.sourceforge.net/gazebo/xmlschema/#controller"
	xmlns:interface="http://playerstage.sourceforge.net/gazebo/xmlschema/#interface"
        xmlns:xacro="http://ros.org/wiki/xacro">

  <include filename="$(find cob_description)/ros/urdf/arm_v0/arm.gazebo.xacro" />
  <include filename="$(find cob_description)/ros/urdf/arm_v0/arm.transmission.xacro" />

<!--####################################################################-->
                       <!--Fix Some Parameters Later-->
<!--####################################################################-->

  <xacro:macro name="cob_arm_v0" params="parent name *origin">

       <!--joint between base_link and arm_0_link -->
        <joint name="${name}_0_joint" type="fixed" >
          <insert_block name="origin" />
          <parent link="${parent}" />
          <child link="${name}_0_link" />
        </joint>

	<link name="${name}_0_link">
		<inertial>
		   <origin xyz="0 0 0" rpy="0 0 0"/>
		   <mass value="1.0"/>
		   <inertia ixx="0.01"  ixy="0"  ixz="0" iyy="0.01" iyz="0" izz="0.01" />
		</inertial>

		<visual>
		   <origin xyz="0 0 0.005" rpy="0 0 0" />
		   <geometry>
		      <box size="0.01 0.01 0.01"/>
		   </geometry>
		   <material name="Red" />
		</visual>

		<collision>
		   <origin xyz="0 0 0.0005" rpy="0 0 0" />
		   <geometry>
		      <box size="0.001 0.001 0.001"/>
		   </geometry>
		</collision>
	</link>

       <!--joint between arm_0_link and arm_1_link -->
	<joint name="${name}_1_joint" type="revolute">
		<origin xyz="0 0 -0.250" rpy="0 0 0"/>
		<parent link="${name}_0_link"/>
		<child link="${name}_1_link"/>
		<axis xyz="0 0 1"/>
	        <calibration reference_position="${arm_1_ref}"/>
		<limit effort="370" velocity="0.4363" lower="-2.0943951" upper="2.0943951"/>
	</joint>

	<link name="${name}_1_link">
		<inertial>
			<origin xyz="0 0.00923 0.1564" rpy="0 0 0" />
			<mass value="5.9907"/>
			<inertia ixx="0.184545"  ixy="0"  ixz="0" iyy="0.180577" iyz="0.000420" izz="0.016081" />
		</inertial>
		<visual>
			<origin xyz="0 0 0" rpy="0 0 0" />
			<geometry>
				<mesh filename="package://cob_description/ros/meshes/arm_v0/J1.STL" />
			</geometry>
                        <material name="Blue" />  

		</visual>
		<collision>
			<origin xyz="0 0 0" rpy="0 0 0" />
			<geometry>
				<mesh filename="package://cob_description/ros/meshes/arm_v0/J1.STL" />
			</geometry>
		</collision>
	</link>

        <!--joint between arm_1_link and arm_2_link-->	
	<joint name="${name}_2_joint" type="revolute">
		<origin xyz="0 0 0" rpy="1.5708 0 0"/>
		<parent link="${name}_1_link"/>
		<child link="${name}_2_link"/>
		<axis xyz="0 0 1"/>
	        <calibration reference_position="${arm_2_ref}"/>
		<limit effort="370" velocity="0.4363" lower="-2.0943951" upper="2.0943951"/> 
	</joint>

	<link name="${name}_2_link">
		<inertial>
			<origin xyz="0 -0.006249 0.008252" rpy="0 0 0"/>
			<mass value="5.734939"/>
			<inertia ixx="0.020715"  ixy="0"  ixz="0" iyy="0.017585" iyz="-0.000460" izz="0.014454" />
		</inertial>
		<visual>
			<origin xyz="0 0 0" rpy="0 0 0" />
			<geometry>
				<mesh filename="package://cob_description/ros/meshes/arm_v0/J2.STL" />
			</geometry>
                        <material name="Red" /> 
                         
		</visual>
		<collision>
			<origin xyz="0 0 0" rpy="0 0 0" />
			<geometry>
				<mesh filename="package://cob_description/ros/meshes/arm_v0/J2.STL"/>
			</geometry>
		</collision>
	</link>

        <!--joint between arm_2_link and arm_3_link-->	
	<joint name="${name}_3_joint" type="revolute">
		<origin xyz="0 -0.408 0" rpy="-1.5708 0 0"/>
		<parent link="${name}_2_link"/>
		<child link="${name}_3_link"/>
		<axis xyz="0 0 1"/>
	        <calibration reference_position="${arm_3_ref}"/>
		<limit effort="176" velocity="0.4189" lower="-6.2831853" upper="6.2831853"/> 
	</joint>

	<link name="${name}_3_link">
		<inertial>
			<origin xyz="0 0.007908 0.192805" rpy="0 0 0"/>
			<mass value="4.214668"/>
			<inertia ixx="0.192416"  ixy="0"  ixz="0" iyy="0.190323" iyz="0.000310" izz="0.008570" />
		</inertial>
		<visual>
			<origin xyz="0 0 0" rpy="0 0 0" /> 
			<geometry>
				<mesh filename="package://cob_description/ros/meshes/arm_v0/J3.STL" />
			</geometry>
                        <material name="Blue" /> 
                          
		</visual>
		<collision>
			<origin xyz="0 0 0" rpy="0 0 0" />
			<geometry>
				<mesh filename="package://cob_description/ros/meshes/arm_v0/J3.STL"/>
			</geometry>
		</collision>
	</link>	

         <!--joint between arm_3_link and arm_4_link-->
	<joint name="${name}_4_joint" type="revolute">
		<origin xyz="0 0 0" rpy="1.5708 0 0" />
		<parent link="${name}_3_link"/>
		<child link="${name}_4_link"/>
		<axis xyz="0 0 1" />
	        <calibration reference_position="${arm_4_ref}"/>
		<limit effort="176" velocity="0.4189" upper="2.0943951" lower="-2.0943951" /> 
	</joint>

	<link name="${name}_4_link">
		<inertial>
			<origin xyz="0 -0.006319 0.009681" rpy="0 0 0"/>
			<mass value="3.669819"/>
			<inertia ixx="0.010547"  ixy="0"  ixz="0" iyy="0.008708" iyz="-0.000335" izz="0.006913" />
		</inertial>
		<visual>
			<origin xyz="0 0 0" rpy="0 0 0" />
			<geometry>
				<mesh filename="package://cob_description/ros/meshes/arm_v0/J4.STL" />
			</geometry>
                        <material name="Red" /> 
                        
		</visual>
		<collision>
			<origin xyz="0 0 0" rpy="0 0 0" />
			<geometry>
				<mesh filename="package://cob_description/ros/meshes/arm_v0/J4.STL"/>
			</geometry>
		</collision>
	</link>

        <!--joint between arm_4_link and arm_5_link-->
	<joint name="${name}_5_joint" type="revolute">
		<origin xyz="0 -0.3165 0" rpy="-1.5708 0 0" />
		<parent link="${name}_4_link"/>
		<child link="${name}_5_link"/>
		<axis xyz="0 0 1" />
	        <calibration reference_position="${arm_5_ref}"/>
		<limit effort="41.6" velocity="0.4363" upper="6.2831853" lower="-6.2831853" />
	</joint>

	<link name="${name}_5_link">
		<inertial>
			<origin xyz="0 -0.004963 0.008394" rpy="0 0 0"/>
			<mass value="2.313272"/>
			<inertia ixx="0.004108"  ixy="0"  ixz="0" iyy="0.003468" iyz="-0.000103" izz="0.002507" />
		</inertial>
		<visual>
			<origin xyz="0 0 0" rpy="0 0 0" />
			<geometry>
				<mesh filename="package://cob_description/ros/meshes/arm_v0/J5.STL" />
			</geometry>
                        <material name="Blue" /> 
                        
		</visual>
		<collision>
			<origin xyz="0 0 0" rpy="0 0 0" />
			<geometry>
				<mesh filename="package://cob_description/ros/meshes/arm_v0/J5.STL"/>
			</geometry>
		</collision>
	</link>

	<!--joint between arm_5_link and arm_6_link-->
	<joint name="${name}_6_joint" type="revolute">
		<origin xyz="0 0 0" rpy="1.5708 0 0" />
		<parent link="${name}_5_link"/>
		<child link="${name}_6_link"/>
		<axis xyz="0 0 1" />
	        <calibration reference_position="${arm_6_ref}"/>
		<limit effort="20.1" velocity="0.4363" upper="2.0943951" lower="-2.0943951" /> 
	</joint>
	
	<link name="${name}_6_link">
		<inertial>
			<origin xyz="0 0 0" rpy="0 0 0"/>
			<mass value="1.1"/>
			<inertia ixx="0.01"  ixy="0"  ixz="0" iyy="0.01" iyz="0" izz="0.01" />
		</inertial>
		<visual>
			<origin xyz="0 0 0" rpy="0 0 0" />
			<geometry>
				<mesh filename="package://cob_description/ros/meshes/arm_v0/J6.STL" />
			</geometry>
                        <material name="Red" /> 
                       
		</visual>
		<collision>
			<origin xyz="0 0 0" rpy="0 0 0" />
			<geometry>
				<mesh filename="package://cob_description/ros/meshes/arm_v0/J6.STL"/>
			</geometry>
		</collision>
	</link>

	<!--joint between arm_6_link and arm_7_link-->
	<joint name="${name}_7_joint" type="revolute">
		<origin xyz="0 -0.1927 0" rpy="-1.5708 0 0" />
		<parent link="${name}_6_link"/>
		<child link="${name}_7_link"/>
		<axis xyz="0 0 1" />
	        <calibration reference_position="${arm_7_ref}"/>
		<limit effort="9.6" velocity="0.8727" upper="6.2831853" lower="-6.2831853" /> 
	</joint>
	
	<link name="${name}_7_link">
		<inertial>
			<origin xyz="0 0 0" rpy="0 0 0"/>
			<mass value="0.5"/>
			<inertia ixx="0.01"  ixy="0"  ixz="0" iyy="0.01" iyz="0" izz="0.01" />
		</inertial>
		<visual>
			<origin xyz="0 0 0" rpy="0 0 0" />
			<geometry>
				<mesh filename="package://cob_description/ros/meshes/arm_v0/J7.STL" />
			</geometry>
                        <material name="Blue" /> 
                       
		</visual>
		<collision>
			<origin xyz="0 0 0" rpy="0 0 0" />
			<geometry>
				<mesh filename="package://cob_description/ros/meshes/arm_v0/J7.STL"/>
			</geometry>
		</collision>
	</link>

        <!-- extensions -->
        <xacro:cob_arm_gazebo_v0 name="${name}" />
        <xacro:cob_arm_transmission_v0 name="${name}" />

  </xacro:macro>

</robot>
