<?xml version="1.0"?>
<robot xmlns:sensor="http://playerstage.sourceforge.net/gazebo/xmlschema/#sensor"
       xmlns:controller="http://playerstage.sourceforge.net/gazebo/xmlschema/#controller"
       xmlns:interface="http://playerstage.sourceforge.net/gazebo/xmlschema/#interface"
       xmlns:xacro="http://ros.org/wiki/xacro">

	<include filename="$(find cob_description)/urdf/tray/tray.gazebo.xacro" />
	<include filename="$(find cob_description)/urdf/tray/tray.transmission.xacro" />

	<xacro:macro name="cob_tray" params="name parent *origin">

		<!-- joint between base_link and tray_link -->
		<joint name="${name}_joint" type="revolute">
			<insert_block name="origin" />
			<parent link="${parent}"/>
			<child link="${name}_link"/>
			<axis xyz="0 0 1" />
			<calibration rising="${tray_ref}"/>
			<dynamics damping="5.0" friction="0.5"/>
			<limit effort="100" lower="-3.31612" upper="0.2" velocity="5"/>
		</joint>

		<link name="${name}_link">
			<inertial>
				<origin xyz="0 0 0" rpy="0 0 0"/>
				<mass value="0.1"/>
				<inertia ixx="0.01" ixy="0" ixz="0" iyy="0.01" iyz="0" izz="0.01" />
			</inertial>

			<visual>
				<origin xyz="0 0 0" rpy="0 0 0" />
				<geometry>
					<mesh filename="package://cob_description/meshes/tray/tray.stl" />
				</geometry>
				<material name="Green" />
			</visual>

			<collision>
				<origin xyz="0 0 0" rpy="0 0 0" />
				<geometry>
					<mesh filename="package://cob_description/meshes/tray/tray_collision.stl" />
				</geometry>
			</collision>
		</link>

		<!-- additional links at the corners of the tray -->
		<joint name="${name}_base_joint" type="fixed" >
			<origin xyz="0 0 0" rpy="-2.3561 0 0"/>
			<parent link="${name}_link" />
			<child link="${name}_base_link" />
		</joint>

		<link name="${name}_base_link"/>

		<joint name="${name}_right_joint" type="fixed" >
			<origin xyz="0.4 -0.3 0.1" rpy="0 0 0"/>
			<parent link="${name}_base_link" />
			<child link="${name}_right_link" />
		</joint>

		<link name="${name}_right_link"/>

		<joint name="${name}_left_joint" type="fixed" >
			<origin xyz="0.4 0.05 0.1" rpy="0 0 0"/>
			<parent link="${name}_base_link" />
			<child link="${name}_left_link" />
		</joint>

		<link name="${name}_left_link"/>

		<!-- extensions -->
		<xacro:cob_tray_gazebo name="${name}" />
		<xacro:cob_tray_transmission name="${name}" />

	</xacro:macro>
	
</robot>
